Workbook

Sheet Articles
A1: ID | B1: Titre article | C1: Slug (URL) | D1: Catégorie | E1: Target keyword | F1: Mots-clés secondaires | G1: Longueur estimée (mots) | H1: Type contenu | I1: SEO Difficulty (0-100) | J1: Potentiel trafic | K1: Priority | L1: Status | M1: Date publication planifiée | N1: Auteur assigné | O1: Notes
A2: 1 | B2: Comment déboucher un tuyau sans plombier : 7 méthodes efficaces | C2: plomberie/comment-deboucher-un-tuyau-sans-plombier-7-methodes-efficaces | D2: plomberie | E2: déboucher tuyau sans plombier | F2: déboucher canalisation maison, astuce plomberie | G2: 1800 | H2: how-to | I2: 38 | J2: Élevé (1000-1500/mois) | K2: haute | L2: published | M2: 46237 | N2: Karim (Expert Plomberie) | O2: Article pilier plomberie, cibler featured snippet
A3: 2 | B3: Réparer un robinet qui fuit : guide étape par étape | C3: plomberie/reparer-un-robinet-qui-fuit-guide-etape-par-etape | D3: plomberie | E3: réparer robinet qui fuit | F3: robinet qui goutte solution, joint robinet | G3: 1600 | H3: how-to | I3: 32 | J3: Élevé (900-1300/mois) | K3: haute | L3: writing | M3: 46237 | N3: Karim (Expert Plomberie) | O3: Ajouter schéma + vidéo courte
A4: 3 | B4: Installer une baignoire soi-même : guide complet 2026 | C4: plomberie/installer-une-baignoire-soi-meme-guide-complet-2026 | D4: plomberie | E4: installer baignoire soi-même | F4: pose baignoire tutoriel, plomberie salle de bain | G4: 2000 | H4: guide | I4: 45 | J4: Moyen (300-500/mois) | K4: moyenne | L4: draft | M4: 46293 | N4: Karim (Expert Plomberie) | O4: Prévoir avertissement sécurité / recommander pro si complexe
A5: 4 | B5: Enlever le calcaire dans les tuyauteries : solutions naturelles | C5: plomberie/enlever-le-calcaire-dans-les-tuyauteries-solutions-naturelles | D5: plomberie | E5: enlever calcaire tuyauterie | F5: calcaire eau Maroc, détartrer canalisation | G5: 1500 | H5: tips | I5: 28 | J5: Moyen (400-600/mois) | K5: moyenne | L5: draft | M5: 46300 | N5: Nadia (Redactrice) | O5: Lien interne vers article entretien plomberie
A6: 5 | B6: Urgence plomberie à 3h du matin : les bons réflexes | C6: plomberie/urgence-plomberie-a-3h-du-matin-les-bons-reflexes | D6: plomberie | E6: urgence plomberie nuit Maroc | F6: plombier urgence 24h/24, fuite eau nuit | G6: 1400 | H6: guide | I6: 25 | J6: Élevé (700-1000/mois) | K6: haute | L6: review | M6: 46244 | N6: Sara (Redactrice SEO) | O6: CTA fort vers réservation urgente FixNow
A7: 6 | B7: Fuite d'eau sous l'évier : causes et solutions rapides | C7: plomberie/fuite-d-eau-sous-l-evier-causes-et-solutions-rapides | D7: plomberie | E7: fuite eau évier cuisine | F7: siphon qui fuit, réparation évier | G7: 1500 | H7: how-to | I7: 30 | J7: Moyen (500-700/mois) | K7: moyenne | L7: draft | M7: 46300 | N7: Karim (Expert Plomberie)
A8: 7 | B8: Chauffe-eau qui ne chauffe plus : diagnostic complet | C8: plomberie/chauffe-eau-qui-ne-chauffe-plus-diagnostic-complet | D8: plomberie | E8: chauffe-eau ne chauffe plus | F8: panne chauffe-eau solution, réparer ballon eau chaude | G8: 1700 | H8: guide | I8: 35 | J8: Élevé (800-1200/mois) | K8: haute | L8: draft | M8: 46244 | N8: Karim (Expert Plomberie) | O8: Forte intention de réservation, article prioritaire
A9: 8 | B9: Combien coûte un plombier à Casablanca en 2026 ? | C9: plomberie/combien-coute-un-plombier-a-casablanca-en-2026 | D9: plomberie | E9: prix plombier Casablanca | F9: tarif plombier Maroc, devis plomberie Casablanca | G9: 1300 | H9: guide | I9: 22 | J9: Élevé (1200-1800/mois) | K9: haute | L9: draft | M9: 46251 | N9: Sara (Redactrice SEO) | O9: SEO local fort, dupliquer pour Rabat/Fès/Marrakech
A10: 9 | B10: WC bouché : 7 astuces pour le déboucher soi-même | C10: plomberie/wc-bouche-7-astuces-pour-le-deboucher-soi-meme | D10: plomberie | E10: wc bouché que faire | F10: déboucher toilettes maison, ventouse wc | G10: 1400 | H10: tips | I10: 27 | J10: Élevé (900-1300/mois) | K10: moyenne | L10: draft | M10: 46307 | N10: Nadia (Redactrice)
A11: 10 | B11: Choisir le bon plombier à Fès : guide complet | C11: plomberie/choisir-le-bon-plombier-a-fes-guide-complet | D11: plomberie | E11: meilleur plombier Fès | F11: plombier Fès avis, artisan plomberie Fès | G11: 1300 | H11: guide | I11: 20 | J11: Moyen (300-500/mois) | K11: basse | L11: draft | M11: 46370 | N11: Sara (Redactrice SEO) | O11: Décliner par ville prioritaire ensuite
A12: 11 | B12: Pression d'eau faible dans la maison : solutions | C12: plomberie/pression-d-eau-faible-dans-la-maison-solutions | D12: plomberie | E12: pression eau faible maison | F12: augmenter pression eau robinet, problème pression Maroc | G12: 1500 | H12: how-to | I12: 26 | J12: Moyen (400-600/mois) | K12: moyenne | L12: draft | M12: 46307 | N12: Karim (Expert Plomberie)
A13: 12 | B13: Entretien annuel de la plomberie : checklist complète | C13: plomberie/entretien-annuel-de-la-plomberie-checklist-complete | D13: plomberie | E13: entretien plomberie maison | F13: checklist plomberie maison, prévenir fuite eau | G13: 1600 | H13: guide | I13: 24 | J13: Faible (150-300/mois) | K13: basse | L13: draft | M13: 46370 | N13: Nadia (Redactrice) | O13: Contenu evergreen, lien interne vers plusieurs articles
A14: 13 | B14: Comment changer une prise électrique au Maroc : tutoriel sécurisé | C14: electricite/comment-changer-une-prise-electrique-au-maroc-tutoriel-securise | D14: électricité | E14: changer prise électrique Maroc | F14: installer prise électrique maison, norme électrique Maroc | G14: 1700 | H14: how-to | I14: 30 | J14: Élevé (700-1000/mois) | K14: haute | L14: writing | M14: 46251 | N14: Yassine (Expert Électricité) | O14: Insister sur sécurité / couper le disjoncteur
A15: 14 | B15: Installer une suspension ou un lustre soi-même | C15: electricite/installer-une-suspension-ou-un-lustre-soi-meme | D15: électricité | E15: installer suspension lampe plafond | F15: poser luminaire plafond, câblage suspension | G15: 1500 | H15: how-to | I15: 25 | J15: Moyen (400-600/mois) | K15: moyenne | L15: draft | M15: 46314 | N15: Yassine (Expert Électricité)
A16: 15 | B16: Disjoncteur qui saute : causes et solutions | C16: electricite/disjoncteur-qui-saute-causes-et-solutions | D16: électricité | E16: disjoncteur qui saute solution | F16: coupure électrique disjoncteur, court-circuit maison | G16: 1600 | H16: guide | I16: 33 | J16: Élevé (900-1300/mois) | K16: haute | L16: draft | M16: 46258 | N16: Yassine (Expert Électricité) | O16: Fort volume, article prioritaire Q3
A17: 16 | B17: Tableau électrique qui grille : que faire immédiatement ? | C17: electricite/tableau-electrique-qui-grille-que-faire-immediatement | D17: électricité | E17: tableau électrique qui grille | F17: odeur brûlé tableau électrique, danger électrique maison | G17: 1400 | H17: guide | I17: 28 | J17: Moyen (300-500/mois) | K17: haute | L17: draft | M17: 46258 | N17: Yassine (Expert Électricité) | O17: Angle sécurité/urgence, CTA réservation urgente
A18: 17 | B18: Norme électrique maison au Maroc : ce qu'il faut savoir | C18: electricite/norme-electrique-maison-au-maroc-ce-qu-il-faut-savoir | D18: électricité | E18: norme électrique maison Maroc | F18: réglementation électrique Maroc, mise aux normes électrique | G18: 1800 | H18: guide | I18: 20 | J18: Faible (150-300/mois) | K18: basse | L18: draft | M18: 46377 | N18: Sara (Redactrice SEO) | O18: Contenu informatif, positionnement expertise
A19: 18 | B19: Panne de courant partielle dans la maison : diagnostic | C19: electricite/panne-de-courant-partielle-dans-la-maison-diagnostic | D19: électricité | E19: panne électrique partielle maison | F19: une pièce sans électricité, panne courant partielle | G19: 1500 | H19: how-to | I19: 27 | J19: Moyen (400-600/mois) | K19: moyenne | L19: draft | M19: 46314 | N19: Yassine (Expert Électricité)
A20: 19 | B20: Installer une prise USB murale : tutoriel pas à pas | C20: electricite/installer-une-prise-usb-murale-tutoriel-pas-a-pas | D20: électricité | E20: installer prise usb murale | F20: prise usb intégrée maison, rénovation électrique moderne | G20: 1200 | H20: how-to | I20: 18 | J20: Faible (100-250/mois) | K20: basse | L20: draft | M20: 46377 | N20: Amine (Redacteur)
A21: 20 | B21: Électricien agréé à Rabat : comment bien choisir | C21: electricite/electricien-agree-a-rabat-comment-bien-choisir | D21: électricité | E21: électricien Rabat prix | F21: meilleur électricien Rabat, tarif électricien Maroc | G21: 1300 | H21: guide | I21: 21 | J21: Moyen (300-500/mois) | K21: moyenne | L21: draft | M21: 46321 | N21: Sara (Redactrice SEO) | O21: SEO local, dupliquer pour autres villes
A22: 21 | B22: Odeur de brûlé au niveau d'une prise électrique : danger et solution | C22: electricite/odeur-de-brule-au-niveau-d-une-prise-electrique-danger-et-solution | D22: électricité | E22: odeur brûlé prise électrique | F22: prise électrique chaude danger, risque incendie électrique | G22: 1400 | H22: guide | I22: 24 | J22: Moyen (350-550/mois) | K22: haute | L22: draft | M22: 46265 | N22: Yassine (Expert Électricité) | O22: Angle sécurité fort, potentiel viral réseaux sociaux
A23: 22 | B23: Rénover l'installation électrique d'un vieil appartement | C23: electricite/renover-l-installation-electrique-d-un-vieil-appartement | D23: électricité | E23: rénovation électrique appartement ancien | F23: mise aux normes appartement ancien, budget rénovation électrique | G23: 1900 | H23: guide | I23: 29 | J23: Moyen (300-500/mois) | K23: moyenne | L23: draft | M23: 46321 | N23: Nadia (Redactrice) | O23: Lien vers article budget travaux général
A24: 23 | B24: Réparer une porte qui grince ou qui coince : guide rapide | C24: menuiserie/reparer-une-porte-qui-grince-ou-qui-coince-guide-rapide | D24: menuiserie | E24: réparer porte qui coince | F24: porte qui grince solution, ajuster porte bois | G24: 1400 | H24: how-to | I24: 24 | J24: Moyen (400-600/mois) | K24: moyenne | L24: draft | M24: 46328 | N24: Omar (Expert Menuiserie)
A25: 24 | B25: Installer une étagère murale soi-même : tutoriel complet | C25: menuiserie/installer-une-etagere-murale-soi-meme-tutoriel-complet | D25: menuiserie | E25: installer étagère murale | F25: fixer étagère mur, étagère bois maison | G25: 1300 | H25: how-to | I25: 20 | J25: Moyen (300-500/mois) | K25: basse | L25: draft | M25: 46384 | N25: Omar (Expert Menuiserie)
A26: 25 | B26: Poncer et vernir un meuble en bois : guide débutant | C26: menuiserie/poncer-et-vernir-un-meuble-en-bois-guide-debutant | D26: menuiserie | E26: poncer vernir meuble bois | F26: rénover meuble ancien bois, vernis meuble tutoriel | G26: 1600 | H26: how-to | I26: 22 | J26: Faible (200-350/mois) | K26: basse | L26: draft | M26: 46384 | N26: Amine (Redacteur)
A27: 26 | B27: Remplacer une serrure de porte : guide complet sécurité | C27: menuiserie/remplacer-une-serrure-de-porte-guide-complet-securite | D27: menuiserie | E27: remplacer serrure porte maison | F27: changer serrure après perte clés, serrure sécurité maison | G27: 1500 | H27: how-to | I27: 27 | J27: Élevé (600-900/mois) | K27: haute | L27: draft | M27: 46265 | N27: Omar (Expert Menuiserie) | O27: Intention sécurité forte, bon taux de conversion attendu
A28: 27 | B28: Fenêtre en bois qui ne ferme plus : causes et solutions | C28: menuiserie/fenetre-en-bois-qui-ne-ferme-plus-causes-et-solutions | D28: menuiserie | E28: fenêtre bois ne ferme plus | F28: fenêtre bois bloquée, réparer fenêtre bois | G28: 1400 | H28: how-to | I28: 21 | J28: Moyen (300-500/mois) | K28: moyenne | L28: draft | M28: 46328 | N28: Omar (Expert Menuiserie)
A29: 28 | B29: Fabriquer une bibliothèque sur mesure : conseils pratiques | C29: menuiserie/fabriquer-une-bibliotheque-sur-mesure-conseils-pratiques | D29: menuiserie | E29: bibliothèque bois sur mesure | F29: meuble bois sur mesure prix, rangement salon bois | G29: 1700 | H29: guide | I29: 19 | J29: Faible (150-300/mois) | K29: basse | L29: draft | M29: 46391 | N29: Amine (Redacteur)
A30: 29 | B30: Menuisier à Marrakech : prix et conseils pour bien choisir | C30: menuiserie/menuisier-a-marrakech-prix-et-conseils-pour-bien-choisir | D30: menuiserie | E30: menuisier Marrakech prix | F30: artisan menuisier Marrakech, tarif menuiserie Maroc | G30: 1300 | H30: guide | I30: 18 | J30: Moyen (250-450/mois) | K30: moyenne | L30: draft | M30: 46335 | N30: Sara (Redactrice SEO) | O30: SEO local, dupliquer pour Agadir/Tanger
A31: 30 | B31: Réparer un parquet abîmé soi-même : guide étape par étape | C31: menuiserie/reparer-un-parquet-abime-soi-meme-guide-etape-par-etape | D31: menuiserie | E31: réparer parquet abîmé | F31: rayure parquet solution, rénover parquet bois | G31: 1500 | H31: how-to | I31: 23 | J31: Moyen (300-500/mois) | K31: moyenne | L31: draft | M31: 46335 | N31: Omar (Expert Menuiserie)
A32: 31 | B32: Installer un dressing sur mesure : budget et étapes | C32: menuiserie/installer-un-dressing-sur-mesure-budget-et-etapes | D32: menuiserie | E32: installer dressing sur mesure | F32: prix dressing sur mesure Maroc, aménagement dressing | G32: 1600 | H32: guide | I32: 26 | J32: Moyen (350-550/mois) | K32: moyenne | L32: draft | M32: 46342 | N32: Nadia (Redactrice)
A33: 32 | B33: Choisir le bois pour ses meubles d'extérieur au Maroc | C33: menuiserie/choisir-le-bois-pour-ses-meubles-d-exterieur-au-maroc | D33: menuiserie | E33: bois meuble extérieur Maroc | F33: mobilier bois résistant climat Maroc, terrasse bois entretien | G33: 1500 | H33: tips | I33: 17 | J33: Faible (100-250/mois) | K33: basse | L33: draft | M33: 46391 | N33: Amine (Redacteur)
A34: 33 | B34: Portail en bois qui se déforme : que faire ? | C34: menuiserie/portail-en-bois-qui-se-deforme-que-faire | D34: menuiserie | E34: portail bois déformé solution | F34: entretien portail bois, réparer portail extérieur | G34: 1300 | H34: how-to | I34: 16 | J34: Faible (100-200/mois) | K34: basse | L34: draft | M34: 46398 | N34: Omar (Expert Menuiserie)
A35: 34 | B35: Rénover une cuisine en bois : idées et budget 2026 | C35: menuiserie/renover-une-cuisine-en-bois-idees-et-budget-2026 | D35: menuiserie | E35: rénover cuisine bois budget | F35: prix rénovation cuisine Maroc, cuisine bois moderne | G35: 1900 | H35: guide | I35: 31 | J35: Élevé (600-900/mois) | K35: haute | L35: draft | M35: 46272 | N35: Sara (Redactrice SEO) | O35: Fort potentiel commercial, cross-sell avec artisans multi-métiers
A36: 35 | B36: Isolation phonique d'une porte : meilleures solutions en bois | C36: menuiserie/isolation-phonique-d-une-porte-meilleures-solutions-en-bois | D36: menuiserie | E36: isolation phonique porte bois | F36: réduire bruit porte appartement, porte insonorisée prix | G36: 1400 | H36: tips | I36: 19 | J36: Faible (150-300/mois) | K36: basse | L36: draft | M36: 46398 | N36: Amine (Redacteur)
A37: 36 | B37: Trouver des artisans fiables à Fès : le guide complet 2026 | C37: conseils/trouver-des-artisans-fiables-a-fes-le-guide-complet-2026 | D37: général | E37: artisans fiables Fès | F37: meilleur artisan Fès, artisan sérieux Fès avis | G37: 1600 | H37: guide | I37: 24 | J37: Moyen (400-600/mois) | K37: haute | L37: writing | M37: 46272 | N37: Sara (Redactrice SEO) | O37: Article pilier local, décliner pour chaque ville FixNow
A38: 37 | B38: Combien coûte la rénovation d'une maison au Maroc ? | C38: conseils/combien-coute-la-renovation-d-une-maison-au-maroc | D38: général | E38: coût rénovation maison Maroc | F38: budget rénovation Maroc, prix travaux maison 2026 | G38: 2000 | H38: guide | I38: 34 | J38: Élevé (1000-1500/mois) | K38: haute | L38: review | M38: 46279 | N38: Sara (Redactrice SEO) | O38: Article pilier budget, lien vers tous les articles prix
A39: 38 | B39: Comment choisir un artisan sur une application comme FixNow | C39: conseils/comment-choisir-un-artisan-sur-une-application-comme-fixnow | D39: général | E39: choisir artisan application Maroc | F39: app artisan Maroc avis, réserver artisan en ligne | G39: 1500 | H39: guide | I39: 20 | J39: Moyen (300-500/mois) | K39: haute | L39: draft | M39: 46279 | N39: Amine (Redacteur) | O39: Contenu produit, pousser inscription app
A40: 39 | B40: 10 erreurs à éviter avant de rénover son logement | C40: conseils/10-erreurs-a-eviter-avant-de-renover-son-logement | D40: général | E40: erreurs rénovation logement | F40: conseils avant travaux maison, éviter erreurs rénovation | G40: 1600 | H40: tips | I40: 23 | J40: Moyen (350-550/mois) | K40: moyenne | L40: draft | M40: 46342 | N40: Nadia (Redactrice)
...

Sheet Statistiques
A1: Statistiques – Plan éditorial Blog FixNow
A3: Répartition par catégorie | D3: Répartition par priorité | G3: Répartition par statut
A4: Catégorie | B4: Nb articles | D4: Priority | E4: Nb articles | G4: Status | H4: Nb articles
A5: plomberie | B5: =COUNTIF(Articles!$D$2:$D$51,A5) | D5: haute | E5: =COUNTIF(Articles!$K$2:$K$51,D5) | G5: draft | H5: =COUNTIF(Articles!$L$2:$L$51,G5)
A6: électricité | B6: =COUNTIF(Articles!$D$2:$D$51,A6) | D6: moyenne | E6: =COUNTIF(Articles!$K$2:$K$51,D6) | G6: writing | H6: =COUNTIF(Articles!$L$2:$L$51,G6)
A7: menuiserie | B7: =COUNTIF(Articles!$D$2:$D$51,A7) | D7: basse | E7: =COUNTIF(Articles!$K$2:$K$51,D7) | G7: review | H7: =COUNTIF(Articles!$L$2:$L$51,G7)
A8: général | B8: =COUNTIF(Articles!$D$2:$D$51,A8) | G8: published | H8: =COUNTIF(Articles!$L$2:$L$51,G8)
A9: Total | B9: =SUM(B5:B8)
A12: Répartition par type de contenu | D12: Indicateurs clés
A13: Type contenu | B13: Nb articles | D13: Total articles | E13: =COUNTA(Articles!$A$2:$A$51)
A14: how-to | B14: =COUNTIF(Articles!$H$2:$H$51,A14) | D14: Longueur moyenne (mots) | E14: =ROUND(AVERAGE(Articles!$G$2:$G$51),0)
A15: tips | B15: =COUNTIF(Articles!$H$2:$H$51,A15) | D15: SEO Difficulty moyenne | E15: =ROUND(AVERAGE(Articles!$I$2:$I$51),0)
A16: guide | B16: =COUNTIF(Articles!$H$2:$H$51,A16) | D16: Articles priorité haute | E16: =COUNTIF(Articles!$K$2:$K$51,"haute")
A17: produit | B17: =COUNTIF(Articles!$H$2:$H$51,A17) | D17: Articles publiés | E17: =COUNTIF(Articles!$L$2:$L$51,"published")
D18: % articles publiés | E18: =ROUND(D18/D14*100,0)&"%"

Sheet Stratégie SEO
B1: Stratégie SEO – Blog FixNow
B3: 1. Ciblage mots-clés
B4: • Privilégier les mots-clés longue traîne (ex. « déboucher tuyau Fès » plutôt que « tuyau »).
B5: • Combiner intention + métier + ville pour capter la recherche locale (Casablanca, Rabat, Fès, Marrakech, Tanger, Agadir).
B6: • 1 target keyword principal + 2-3 mots-clés secondaires par article (voir feuille Articles).
B8: 2. Structure de contenu
B9: • 1500 mots minimum par article (guides piliers : 1800-2000 mots).
B10: • Structure H1 unique, puis H2/H3 hiérarchisés reprenant les variantes du mot-clé.
B11: • Introduction avec réponse directe (featured snippet), FAQ en fin d'article recommandée.
B13: 3. Maillage interne
B14: • Chaque article doit renvoyer vers 2-3 articles connexes du blog.
B15: • Lien systématique vers la page de réservation / recherche d'artisan de l'app FixNow.
... B26: • Dupliquer les articles locaux performants sur les autres villes couvertes par FixNow.
